<?xml version="1.0" encoding="utf-8"?>
<!-- =================================================================================== -->
<!-- |    This document was autogenerated by xacro from podi.urdf.xacro                | -->
<!-- |    EDITING THIS FILE BY HAND IS NOT RECOMMENDED                                 | -->
<!-- =================================================================================== -->
<robot name="podi">
  <!-- Chassis -->
  <link name="base_link">
    <inertial>
      <mass value="3.5"/>
      <!--<origin xyz="-0.025 0 -0.223"/>-->
      <origin xyz="0 0 0"/>
      <inertia ixx="1" ixy="0" ixz="0" iyy="1" iyz="0" izz="1"/>
    </inertial>
    <visual>
      <origin rpy="0 0 0" xyz="-0.045 0 0.148"/>
      <geometry name="pioneer_geom">
        <mesh filename="package://tbd_podi_description/meshes/p3dx_meshes/chassis.stl"/>
      </geometry>
      <material name="ChassisRed">
        <color rgba="0.851 0.0 0.0 1.0"/>
      </material>
    </visual>
    <collision>
      <origin rpy="0 0 0" xyz="-0.045 0 0.148"/>
      <geometry>
        <box size="0.35 0.25 0.14"/>
      </geometry>
    </collision>
  </link>
  <gazebo reference="base_link">
    <material>Gazebo/Red</material>
  </gazebo>
  <link name="top_plate">
    <inertial>
      <mass value="0.01"/>
      <origin xyz="0 0 0"/>
      <inertia ixx="1" ixy="0" ixz="0" iyy="1" iyz="0" izz="1"/>
    </inertial>
    <visual>
      <origin rpy="0 0 0" xyz="0 0 0"/>
      <geometry name="pioneer_geom">
        <mesh filename="package://tbd_podi_description/meshes/p3dx_meshes/top.stl"/>
      </geometry>
      <material name="TopBlack">
        <color rgba="0.038 0.038 0.038 1.0"/>
      </material>
    </visual>
    <collision>
      <origin rpy="0 0 0" xyz="0 0 0"/>
      <geometry>
        <box size="0.45 0.38 0.01"/>
      </geometry>
    </collision>
  </link>
  <gazebo reference="top_plate">
    <material>Gazebo/Black</material>
  </gazebo>
  <joint name="base_top_joint" type="fixed">
    <origin rpy="0 0 0" xyz="-0.045 0 0.234"/>
    <axis xzy="0 0 1"/>
    <parent link="base_link"/>
    <child link="top_plate"/>
  </joint>
  <link name="front_sonar">
    <inertial>
      <mass value="0.0001"/>
      <origin xyz="0 0 0"/>
      <inertia ixx="1" ixy="0" ixz="0" iyy="1" iyz="0" izz="1"/>
    </inertial>
    <visual>
      <origin rpy="0 0 0" xyz="0 0 0"/>
      <geometry name="pioneer_geom">
        <mesh filename="package://tbd_podi_description/meshes/p3dx_meshes/front_sonar.stl"/>
      </geometry>
      <material name="SonarYellow">
        <color rgba="0.715 0.583 0.210 1.0"/>
      </material>
    </visual>
  </link>
  <gazebo reference="front_sonar">
    <material value="Gazebo/Yellow"/>
  </gazebo>
  <joint name="base_front_joint" type="fixed">
    <origin rpy="0 0 0" xyz="-0.198 0 0.208"/>
    <parent link="base_link"/>
    <child link="front_sonar"/>
  </joint>
  <joint name="base_back_joint" type="fixed">
    <origin rpy="0 0 0" xyz="0.109 0 0.209"/>
    <parent link="base_link"/>
    <child link="back_sonar"/>
  </joint>
  <link name="back_sonar">
    <inertial>
      <mass value="0"/>
      <origin xyz="0 0 0"/>
      <inertia ixx="1" ixy="0" ixz="0" iyy="1" iyz="0" izz="1"/>
    </inertial>
    <visual>
      <origin rpy="0 0 0" xyz="0 0 0"/>
      <geometry name="pioneer_geom">
        <mesh filename="package://tbd_podi_description/meshes/p3dx_meshes/back_sonar.stl"/>
      </geometry>
      <material name="SonarYellow">
        <color rgba="0.715 0.583 0.210 1.0"/>
      </material>
    </visual>
    <collision>
      <origin rpy="0 0 0" xyz="0 0 0"/>
      <geometry>
        <box size="0 0 0"/>
      </geometry>
    </collision>
  </link>
  <!-- Caster -->
  <joint name="base_caster_swivel_joint" type="continuous">
    <origin rpy="0 0 0" xyz="-0.185 0 0.055"/>
    <axis xyz="0 0 1"/>
    <limit effort="100" k_velocity="0" velocity="100"/>
    <joint_properties damping="0.0" friction="0.0"/>
    <parent link="base_link"/>
    <child link="caster_swivel"/>
  </joint>
  <link name="caster_swivel">
    <inertial>
      <mass value="0.1"/>
      <origin xyz="0 0 0"/>
      <inertia ixx="0.01" ixy="0" ixz="0" iyy="0.01" iyz="0" izz="0.01"/>
    </inertial>
    <visual>
      <origin rpy="0 0 0" xyz="0 0 0"/>
      <geometry name="pioneer_geom">
        <mesh filename="package://tbd_podi_description/meshes/p3dx_meshes/caster_swivel.stl"/>
      </geometry>
      <material name="caster_swivel">
        <color rgba="0.5 0.5 0.5 1"/>
      </material>
    </visual>
  </link>
  <gazebo reference="caster_swivel">
    <material value="Gazebo/Grey"/>
  </gazebo>
  <joint name="caster_swivel_hubcap_joint" type="continuous">
    <origin rpy="0 0 0" xyz="-0.026 0 -0.016"/>
    <axis xyz="0 1 0"/>
    <anchor xyz="0 0 0"/>
    <limit effort="100" k_velocity="0" velocity="100"/>
    <joint_properties damping="0.0" friction="0.0"/>
    <parent link="caster_swivel"/>
    <child link="caster_wheel"/>
  </joint>
  <link name="caster_wheel">
    <inertial>
      <mass value="0.1"/>
      <origin xyz="0 0 0"/>
      <inertia ixx="0.012411765597" ixy="-0.000711733678" ixz="0.00050272983" iyy="0.015218160428" iyz="-0.000004273467" izz="0.011763977943"/>
    </inertial>
    <visual>
      <origin rpy="0 0 0" xyz="0 0 0"/>
      <geometry name="pioneer_geom">
        <mesh filename="package://tbd_podi_description/meshes/p3dx_meshes/caster_wheel.stl"/>
      </geometry>
      <material name="WheelBlack">
        <color rgba="0.117 0.117 0.117 1"/>
      </material>
    </visual>
    <collision>
      <origin rpy="-1.57079635 0 0" xyz="0 0 0"/>
      <geometry>
        <cylinder length="0.01" radius="0.0375"/>
      </geometry>
    </collision>
  </link>
  <gazebo reference="caster_wheel">
    <material>Gazebo/Black</material>
  </gazebo>
  <joint name="caster_wheel_joint" type="fixed">
    <origin rpy="0 0 0" xyz="-0.0035 0 -0.001"/>
    <parent link="caster_wheel"/>
    <child link="caster_hubcap"/>
  </joint>
  <link name="caster_hubcap">
    <inertial>
      <mass value="0.01"/>
      <origin xyz="0 0 0"/>
      <inertia ixx="0.012411765597" ixy="-0.000711733678" ixz="0.00050272983" iyy="0.015218160428" iyz="-0.000004273467" izz="0.011763977943"/>
    </inertial>
    <visual>
      <origin rpy="0 0 0" xyz="0 0 0"/>
      <geometry name="pioneer_geom">
        <mesh filename="package://tbd_podi_description/meshes/p3dx_meshes/caster_hubcap.stl"/>
      </geometry>
      <material name="caster_swivel">
        <color rgba="0.5 0.5 0.5 1"/>
      </material>
    </visual>
    <collision>
      <origin rpy="0 0 0" xyz="0 0 0"/>
      <geometry>
        <box size="0.05 0.05 0.05"/>
      </geometry>
    </collision>
  </link>
  <gazebo reference="caster_hubcap">
    <material value="Gazebo/Grey"/>
  </gazebo>
  <link name="left_wheel">
    <inertial>
      <mass value="0.5"/>
      <origin xyz="0 0 0"/>
      <inertia ixx="0.012411765597" ixy="0" ixz="0" iyy="0.015218160428" iyz="0" izz="0.011763977943"/>
    </inertial>
    <visual>
      <origin rpy="0 0 0" xyz="0 0 0"/>
      <geometry name="pioneer_geom">
        <mesh filename="package://tbd_podi_description/meshes/p3dx_meshes/left_wheel.stl"/>
      </geometry>
      <material name="WheelBlack">
        <color rgba="0.117 0.117 0.117 1"/>
      </material>
    </visual>
    <collision>
      <origin rpy="-1.57079635 0 0" xyz="0 0 0"/>
      <geometry>
        <cylinder length="0.01" radius="0.09"/>
      </geometry>
    </collision>
  </link>
  <joint name="left_hubcap_joint" type="fixed">
    <!--<origin xyz="0 ${reflect*0.158} 0.091" rpy="0 0 0"/>-->
    <origin rpy="0 0 0" xyz="0 0 0"/>
    <parent link="left_wheel"/>
    <child link="left_hubcap"/>
  </joint>
  <link name="left_hubcap">
    <inertial>
      <mass value="0.01"/>
      <origin xyz="0 0 0"/>
      <inertia ixx="0.012411765597" ixy="0" ixz="0" iyy="0.015218160428" iyz="0" izz="0.011763977943"/>
    </inertial>
    <visual>
      <origin rpy="0 0 0" xyz="0 0 0"/>
      <geometry name="pioneer_geom">
        <mesh filename="package://tbd_podi_description/meshes/p3dx_meshes/left_hubcap.stl"/>
      </geometry>
      <material name="HubcapYellow">
        <color rgba="1.0 0.811 0.151 1.0"/>
      </material>
    </visual>
    <collision>
      <origin rpy="0 0 0" xyz="0 0 0"/>
      <geometry>
        <box size="0 0 0"/>
      </geometry>
    </collision>
  </link>
  <!-- Parent to the wheel -->
  <joint name="left_wheel_joint" type="continuous">
    <axis xyz="0 1 0"/>
    <anchor xyz="0 0 0"/>
    <limit effort="100" velocity="100"/>
    <joint_properties damping="0.0" friction="0.0"/>
    <origin rpy="0 0 0" xyz="0 0.158 0.091"/>
    <parent link="base_link"/>
    <child link="left_wheel"/>
  </joint>
  <!-- Transmission variable for gazebo -->
  <transmission name="left_wheel_trans" type="pr2_mechanism_model/SimpleTransmission">
    <type>transmission_interface/SimpleTransmission</type>
    <actuator name="left_wheel_motor">
      <hardwareInterface>hardware_interface/VelocityJointInterface</hardwareInterface>
      <mechanicalReduction>75.0676691729</mechanicalReduction>
    </actuator>
    <joint name="left_wheel_joint">
      <hardwareInterface>hardware_interface/VelocityJointInterface</hardwareInterface>
    </joint>
  </transmission>
  <gazebo reference="left_hubcap">
    <material value="Gazebo/Yellow"/>
  </gazebo>
  <gazebo reference="left_wheel">
    <material value="Gazebo/Black"/>
    <elem key="mu1" value="0.5"/>
    <elem key="mu2" value="50.0"/>
    <elem key="kp" value="100000000.0"/>
    <elem key="kd" value="1.0"/>
  </gazebo>
  <link name="right_wheel">
    <inertial>
      <mass value="0.5"/>
      <origin xyz="0 0 0"/>
      <inertia ixx="0.012411765597" ixy="0" ixz="0" iyy="0.015218160428" iyz="0" izz="0.011763977943"/>
    </inertial>
    <visual>
      <origin rpy="0 0 0" xyz="0 0 0"/>
      <geometry name="pioneer_geom">
        <mesh filename="package://tbd_podi_description/meshes/p3dx_meshes/right_wheel.stl"/>
      </geometry>
      <material name="WheelBlack">
        <color rgba="0.117 0.117 0.117 1"/>
      </material>
    </visual>
    <collision>
      <origin rpy="-1.57079635 0 0" xyz="0 0 0"/>
      <geometry>
        <cylinder length="0.01" radius="0.09"/>
      </geometry>
    </collision>
  </link>
  <joint name="right_hubcap_joint" type="fixed">
    <!--<origin xyz="0 ${reflect*0.158} 0.091" rpy="0 0 0"/>-->
    <origin rpy="0 0 0" xyz="0 0 0"/>
    <parent link="right_wheel"/>
    <child link="right_hubcap"/>
  </joint>
  <link name="right_hubcap">
    <inertial>
      <mass value="0.01"/>
      <origin xyz="0 0 0"/>
      <inertia ixx="0.012411765597" ixy="0" ixz="0" iyy="0.015218160428" iyz="0" izz="0.011763977943"/>
    </inertial>
    <visual>
      <origin rpy="0 0 0" xyz="0 0 0"/>
      <geometry name="pioneer_geom">
        <mesh filename="package://tbd_podi_description/meshes/p3dx_meshes/right_hubcap.stl"/>
      </geometry>
      <material name="HubcapYellow">
        <color rgba="1.0 0.811 0.151 1.0"/>
      </material>
    </visual>
    <collision>
      <origin rpy="0 0 0" xyz="0 0 0"/>
      <geometry>
        <box size="0 0 0"/>
      </geometry>
    </collision>
  </link>
  <!-- Parent to the wheel -->
  <joint name="right_wheel_joint" type="continuous">
    <axis xyz="0 1 0"/>
    <anchor xyz="0 0 0"/>
    <limit effort="100" velocity="100"/>
    <joint_properties damping="0.0" friction="0.0"/>
    <origin rpy="0 0 0" xyz="0 -0.158 0.091"/>
    <parent link="base_link"/>
    <child link="right_wheel"/>
  </joint>
  <!-- Transmission variable for gazebo -->
  <transmission name="right_wheel_trans" type="pr2_mechanism_model/SimpleTransmission">
    <type>transmission_interface/SimpleTransmission</type>
    <actuator name="right_wheel_motor">
      <hardwareInterface>hardware_interface/VelocityJointInterface</hardwareInterface>
      <mechanicalReduction>-75.0676691729</mechanicalReduction>
    </actuator>
    <joint name="right_wheel_joint">
      <hardwareInterface>hardware_interface/VelocityJointInterface</hardwareInterface>
    </joint>
  </transmission>
  <gazebo reference="right_hubcap">
    <material value="Gazebo/Yellow"/>
  </gazebo>
  <gazebo reference="right_wheel">
    <material value="Gazebo/Black"/>
    <elem key="mu1" value="0.5"/>
    <elem key="mu2" value="50.0"/>
    <elem key="kp" value="100000000.0"/>
    <elem key="kd" value="1.0"/>
  </gazebo>
  <create>
    <back_sonar parent="base_link"/>
    <top_plate parent="base_link"/>
  </create>
  <gazebo>
    <plugin filename="libgazebo_ros_diff_drive.so" name="differential_drive_controller">
      <alwaysOn>true</alwaysOn>
      <updateRate>100</updateRate>
      <leftJoint>left_wheel_joint</leftJoint>
      <rightJoint>right_wheel_joint</rightJoint>
      <wheelSeparation>0.158</wheelSeparation>
      <wheelDiameter>0.12</wheelDiameter>
      <torque>5</torque>
      <commandTopic>cmd_vel</commandTopic>
      <robotBaseFrame>base_link</robotBaseFrame>
      <odometryTopic>odom</odometryTopic>
      <odometryFrame>odom</odometryFrame>
    </plugin>
    <!-- TODO include P3D (ground truth) plugin -->
    <!-- XXX old urdf included a gazebo_ros_controller_manager plugin with a 1 second update rate -->
  </gazebo>
  <link name="handle_base">
    <inertial>
      <mass value="1"/>
      <origin xyz="0 0 0"/>
      <inertia ixx="1" ixy="0" ixz="0" iyy="1" iyz="0" izz="1"/>
    </inertial>
    <visual>
      <origin rpy="0 0 0" xyz="0 0 0.02"/>
      <geometry>
        <cylinder length="0.04" radius="0.06"/>
      </geometry>
      <material name="handleBaseBlack">
        <color rgba="1 1 1 1"/>
      </material>
    </visual>
    <collision>
      <origin rpy="0 0 0" xyz="0 0 0.02"/>
      <geometry>
        <cylinder length="0.04" radius="0.06"/>
      </geometry>
    </collision>
  </link>
  <link name="handle_bottom_plate">
    <inertial>
      <mass value="1"/>
      <origin xyz="0 0 0"/>
      <inertia ixx="1" ixy="0" ixz="0" iyy="1" iyz="0" izz="1"/>
    </inertial>
    <visual>
      <origin rpy="0 0 0" xyz="0 0 0"/>
      <geometry>
        <box size="0.09 0.21 0.005"/>
      </geometry>
      <material name="handleBottomBlack">
        <color rgba="1 1 1 1"/>
      </material>
    </visual>
    <collision>
      <origin rpy="0 0 0" xyz="0 0 0"/>
      <geometry>
        <box size="0.09 0.21 0.005"/>
      </geometry>
    </collision>
  </link>
  <link name="handle_back_plate">
    <inertial>
      <mass value="0.01"/>
      <origin xyz="0 0 0"/>
      <inertia ixx="1" ixy="0" ixz="0" iyy="1" iyz="0" izz="1"/>
    </inertial>
    <visual>
      <origin rpy="0 0 0" xyz="-0.07 0 0"/>
      <geometry>
        <box size="0.14 0.155 0.005"/>
      </geometry>
      <material name="handleBackPlateBlack">
        <color rgba="1 1 1 1"/>
      </material>
    </visual>
    <collision>
      <origin rpy="0 0 0" xyz="-0.07 0 0"/>
      <geometry>
        <box size="0.14 0.155 0.005"/>
      </geometry>
    </collision>
  </link>
  <link name="handle_bottom">
    <inertial>
      <mass value="0.01"/>
      <origin xyz="0 0 0"/>
      <inertia ixx="1" ixy="0" ixz="0" iyy="1" iyz="0" izz="1"/>
    </inertial>
    <visual>
      <origin rpy="0 0 0" xyz="-0.16666 0 0.0175"/>
      <geometry>
        <box size="0.33 0.155 0.035"/>
      </geometry>
      <material name="handleBackPlateBlack">
        <color rgba="0 0 0 1"/>
      </material>
    </visual>
    <collision>
      <origin rpy="0 0 0" xyz="-0.16666 0 0.0175"/>
      <geometry>
        <box size="0.33 0.155 0.035"/>
      </geometry>
    </collision>
  </link>
  <link name="handle_top">
    <inertial>
      <mass value="0.01"/>
      <origin xyz="0 0 0"/>
      <inertia ixx="1" ixy="0" ixz="0" iyy="1" iyz="0" izz="1"/>
    </inertial>
    <visual>
      <origin rpy="0 0 0" xyz="-0.0215 0 -0.0175"/>
      <geometry>
        <box size="0.043 0.155 0.035"/>
      </geometry>
      <material name="handleBackPlateBlack">
        <color rgba="0 0 0 1"/>
      </material>
    </visual>
    <collision>
      <origin rpy="0 0 0" xyz="-0.0215 0 -0.0175"/>
      <geometry>
        <box size="0.043 0.155 0.035"/>
      </geometry>
    </collision>
  </link>
  <joint name="handle_base_joint" type="fixed">
    <origin rpy="0 0 0" xyz="-0.13 0 0.234"/>
    <parent link="base_link"/>
    <child link="handle_base"/>
  </joint>
  <joint name="handle_rotation" type="revolute">
    <origin rpy="0 0 0" xyz="0 0 0.04"/>
    <axis xyz="0 0 1"/>
    <parent link="handle_base"/>
    <child link="handle_bottom_plate"/>
    <limit effort="0" lower="-1.57" upper="1.57" velocity="1"/>
  </joint>
  <joint name="handle_bottom_plate_to_back_plate" type="fixed">
    <origin rpy="0 0.785398 0" xyz="0.045 0 0.005"/>
    <parent link="handle_bottom_plate"/>
    <child link="handle_back_plate"/>
  </joint>
  <joint name="handle_back_plate_to_bottom" type="fixed">
    <origin rpy="0 0 0" xyz="-0.14 0 0.005"/>
    <parent link="handle_back_plate"/>
    <child link="handle_bottom"/>
  </joint>
  <joint name="handle_length" type="prismatic">
    <origin rpy="0 0 0" xyz="-0.33 0 0.0275"/>
    <axis xyz="-1 0 0"/>
    <parent link="handle_bottom"/>
    <child link="handle_top"/>
    <limit effort="0" lower="0" upper="0.46" velocity="1"/>
  </joint>
  <link name="laser_scanner">
    <inertial>
      <mass value="1"/>
      <origin xyz="0 0 0"/>
      <inertia ixx="1" ixy="0" ixz="0" iyy="1" iyz="0" izz="1"/>
    </inertial>
    <visual>
      <origin rpy="0 0 0" xyz="0 0 0"/>
      <geometry>
        <box size="0.1 0.1 0.1"/>
      </geometry>
      <material name="laser_scanner_color">
        <color rgba="1 1 1 1"/>
      </material>
    </visual>
    <collision>
      <origin rpy="0 0 0" xyz="0 0 0"/>
      <geometry>
        <box size="0.1 0.1 0.1"/>
      </geometry>
    </collision>
  </link>
  <joint name="laser_scanner_to_base_joint" type="fixed">
    <origin rpy="0 0 0" xyz="0.015 0 0.15"/>
    <parent link="back_sonar"/>
    <child link="laser_scanner"/>
  </joint>
  <link name="podi_face_screen">
    <inertial>
      <mass value="0.5"/>
      <origin xyz="0 0 0"/>
      <inertia ixx="1" ixy="0" ixz="0" iyy="1" iyz="0" izz="1"/>
    </inertial>
    <visual>
      <origin rpy="0 0 0" xyz="0 0 0"/>
      <geometry>
        <box size="0.01 0.2 0.2"/>
      </geometry>
      <material name="laser_scanner_color">
        <color rgba="1 1 1 1"/>
      </material>
    </visual>
    <collision>
      <origin rpy="0 0 0" xyz="0 0 0"/>
      <geometry>
        <box size="0.01 0.2 0.2"/>
      </geometry>
    </collision>
  </link>
  <joint name="screen_to_laser_scanner_joint" type="fixed">
    <origin rpy="0 0 0" xyz="0.0 0 0.25"/>
    <parent link="laser_scanner"/>
    <child link="podi_face_screen"/>
  </joint>
  <link name="podi_display">
    <inertial>
      <mass value="0.01"/>
      <origin xyz="0 0 0"/>
      <inertia ixx="1" ixy="0" ixz="0" iyy="1" iyz="0" izz="1"/>
    </inertial>
    <visual>
      <origin rpy="0 0 0" xyz="0 0 0"/>
      <geometry>
        <box size=" 0.18 0.10125 0.01"/>
      </geometry>
      <material name="podi_display_color">
        <color rgba="0 0 0 1"/>
      </material>
    </visual>
    <collision>
      <origin rpy="0 0 0" xyz="0 0 0"/>
      <geometry>
        <box size=" 0.18 0.10125 0.01"/>
      </geometry>
    </collision>
  </link>
  <joint name="display_to_screen_joint" type="fixed">
    <origin rpy="1.57079635 0 1.57079635" xyz="0.01 0 0"/>
    <parent link="podi_face_screen"/>
    <child link="podi_display"/>
  </joint>
  <link name="podi_front_camera">
    <inertial>
      <mass value="0.01"/>
      <origin xyz="0 0 0"/>
      <inertia ixx="1" ixy="0" ixz="0" iyy="1" iyz="0" izz="1"/>
    </inertial>
    <visual>
      <origin rpy="0 0 0" xyz="0 0 0"/>
      <geometry>
        <box size="0.05 0.05 0.05"/>
      </geometry>
      <material name="laser_scanner_color">
        <color rgba="1 1 1 1"/>
      </material>
    </visual>
    <collision>
      <origin rpy="0 0 0" xyz="0 0 0"/>
      <geometry>
        <box size="0.05 0.05 0.05"/>
      </geometry>
    </collision>
  </link>
  <joint name="camera_to_screen_joint" type="fixed">
    <origin rpy="0 0 0" xyz="0 0 0.21"/>
    <axis xyz="0 1 0"/>
    <parent link="podi_face_screen"/>
    <child link="podi_front_camera"/>
  </joint>
  <gazebo reference="laser_scanner">
    <sensor name="lms100x" type="gpu_ray">
      <pose>0 0 0 0 0 0</pose>
      <!-- <visualize>false</visualize> -->
      <update_rate>20</update_rate>
      <ray>
        <scan>
          <horizontal>
            <samples>360</samples>
            <resolution>1</resolution>
            <min_angle>-1.570796</min_angle>
            <max_angle>1.570796</max_angle>
          </horizontal>
        </scan>
        <range>
          <min>0.10</min>
          <max>30.0</max>
          <resolution>0.01</resolution>
        </range>
        <noise>
          <type>gaussian</type>
          <mean>0.0</mean>
          <stddev>0.01</stddev>
        </noise>
      </ray>
      <plugin filename="libgazebo_ros_gpu_laser.so" name="gazebo_ros_head_hokuyo_controller">
        <topicName>/scan</topicName>
        <frameName>laser_scanner</frameName>
      </plugin>
    </sensor>
  </gazebo>
  <gazebo reference="podi_display">
    <visual>
      <plugin filename="libgazebo_ros_video.so" name="screen_video_controller">
        <height>1080</height>
        <width>1920</width>
        <topicName>/podi_screen</topicName>
      </plugin>
    </visual>
  </gazebo>
  <gazebo reference="podi_front_camera">
    <sensor name="front_camera" type="camera">
      <update_rate>30.0</update_rate>
      <camera name="head">
        <horizontal_fov>1.3962634</horizontal_fov>
        <image>
          <width>1024</width>
          <height>800</height>
          <format>R8G8B8</format>
        </image>
        <clip>
          <near>0.02</near>
          <far>300</far>
        </clip>
        <noise>
          <type>gaussian</type>
          <!-- Noise is sampled independently per pixel on each frame.
               That pixel's noise value is added to each of its color
               channels, which at that point lie in the range [0,1]. -->
          <mean>0.0</mean>
          <stddev>0.007</stddev>
        </noise>
      </camera>
      <plugin filename="libgazebo_ros_camera.so" name="camera_controller">
        <alwaysOn>true</alwaysOn>
        <updateRate>0.0</updateRate>
        <cameraName>/front_camera</cameraName>
        <imageTopicName>image_raw</imageTopicName>
        <cameraInfoTopicName>camera_info</cameraInfoTopicName>
        <frameName>podi_front_camera</frameName>
        <hackBaseline>0.07</hackBaseline>
        <distortionK1>0.0</distortionK1>
        <distortionK2>0.0</distortionK2>
        <distortionK3>0.0</distortionK3>
        <distortionT1>0.0</distortionT1>
        <distortionT2>0.0</distortionT2>
      </plugin>
    </sensor>
  </gazebo>
  <gazebo>
    <plugin filename="libgazebo_ros_control.so" name="gazebo_ros_control">
      <robotNamespace>/podi</robotNamespace>
    </plugin>
  </gazebo>
</robot>

